<?xml version="1.0" ?>
<!-- =================================================================================== -->
<!-- |    This document was autogenerated by xacro from src/description/robot_core.xacro | -->
<!-- |    EDITING THIS FILE BY HAND IS NOT RECOMMENDED                                 | -->
<!-- =================================================================================== -->
<robot>
  <!-- Specify some standard inertial calculations https://en.wikipedia.org/wiki/List_of_moments_of_inertia -->
  <!-- These make use of xacro's mathematical functionality -->
  <!-- Define materials -->
  <material name="white">
    <color rgba="1 1 1 1"/>
  </material>
  <material name="orange">
    <color rgba="1 0.3 0.1 1"/>
  </material>
  <material name="blue">
    <color rgba="0.2 0.2 1 1"/>
  </material>
  <material name="black">
    <color rgba="0 0 0 1"/>
  </material>
  <material name="red">
    <color rgba="1 0 0 1"/>
  </material>
  <material name="purple">
    <color rgba="0.749 0.122 0.729 1"/>
  </material>
  <!-- Base link is the main coordinate frame -->
  <link name="base_link"/>
  <!-- Chassis Joint -->
  <joint name="chassis_joint" type="fixed">
    <parent link="base_link"/>
    <child link="chassis"/>
    <origin xyz="-0.1 0 0"/>
  </joint>
  <!-- Chassis Link -->
  <link name="chassis">
    <visual>
      <origin xyz="0.25 0 0.15"/>
      <geometry>
        <box size="0.5 0.5 0.3"/>
      </geometry>
      <material name="purple"/>
    </visual>
    <collision>
      <origin xyz="0.25 0 0.15"/>
      <geometry>
        <box size="0.5 0.5 0.3"/>
      </geometry>
    </collision>
    <inertial>
      <origin rpy="0 0 0" xyz="0.25 0 0.15"/>
      <mass value="1.0"/>
      <inertia ixx="0.02833333333333333" ixy="0.0" ixz="0.0" iyy="0.02833333333333333" iyz="0.0" izz="0.041666666666666664"/>
    </inertial>
  </link>
  <!-- to visualize color attributes in Gazebo simulator-->
  <gazebo reference="chassis">
    <material>
      <!-- Gazebo Purple color-->
      <ambient>0.5 0.0 0.5 1.0</ambient>
      <diffuse>0.5 0.0 0.5 1.0</diffuse>
      <specular>0.1 0.1 0.1 1.0</specular>
    </material>
  </gazebo>
  <!-- Four-Wheel Configuration -->
  <!-- Front Left Wheel -->
  <joint name="front_left_wheel_joint" type="continuous">
    <parent link="base_link"/>
    <child link="front_left_wheel"/>
    <origin rpy="-1.5707963267948966 0 0" xyz="0.3 0.25 0"/>
    <axis xyz="0 0 1"/>
  </joint>
  <link name="front_left_wheel">
    <visual>
      <geometry>
        <cylinder length="0.04" radius="0.05"/>
      </geometry>
      <material name="black"/>
    </visual>
    <collision>
      <geometry>
        <cylinder length="0.04" radius="0.05"/>
      </geometry>
    </collision>
    <inertial>
      <origin rpy="0 0 0" xyz="0 0 0"/>
      <mass value="0.1"/>
      <inertia ixx="7.583333333333335e-05" ixy="0.0" ixz="0.0" iyy="7.583333333333335e-05" iyz="0.0" izz="0.00012500000000000003"/>
    </inertial>
  </link>
  <gazebo reference="front_left_wheel">
    <material>Gazebo/Black</material>
  </gazebo>
  <!-- Front Right Wheel -->
  <joint name="front_right_wheel_joint" type="continuous">
    <parent link="base_link"/>
    <child link="front_right_wheel"/>
    <origin rpy="1.5707963267948966 0 0" xyz="0.3 -0.25 0"/>
    <axis xyz="0 0 -1"/>
  </joint>
  <link name="front_right_wheel">
    <visual>
      <geometry>
        <cylinder length="0.04" radius="0.05"/>
      </geometry>
      <material name="black"/>
    </visual>
    <collision>
      <geometry>
        <cylinder length="0.04" radius="0.05"/>
      </geometry>
    </collision>
    <inertial>
      <origin rpy="0 0 0" xyz="0 0 0"/>
      <mass value="0.1"/>
      <inertia ixx="7.583333333333335e-05" ixy="0.0" ixz="0.0" iyy="7.583333333333335e-05" iyz="0.0" izz="0.00012500000000000003"/>
    </inertial>
  </link>
  <gazebo reference="front_right_wheel">
    <material>Gazebo/Black</material>
  </gazebo>
  <!-- Rear Left Wheel -->
  <joint name="rear_left_wheel_joint" type="continuous">
    <parent link="base_link"/>
    <child link="rear_left_wheel"/>
    <origin rpy="-1.5707963267948966 0 0" xyz="0 0.25 0"/>
    <axis xyz="0 0 1"/>
  </joint>
  <link name="rear_left_wheel">
    <visual>
      <geometry>
        <cylinder length="0.04" radius="0.05"/>
      </geometry>
      <material name="black"/>
    </visual>
    <collision>
      <geometry>
        <cylinder length="0.04" radius="0.05"/>
      </geometry>
    </collision>
    <inertial>
      <origin rpy="0 0 0" xyz="0 0 0"/>
      <mass value="0.1"/>
      <inertia ixx="7.583333333333335e-05" ixy="0.0" ixz="0.0" iyy="7.583333333333335e-05" iyz="0.0" izz="0.00012500000000000003"/>
    </inertial>
  </link>
  <gazebo reference="rear_left_wheel">
    <material>Gazebo/Black</material>
  </gazebo>
  <!-- Rear Right Wheel -->
  <joint name="rear_right_wheel_joint" type="continuous">
    <parent link="base_link"/>
    <child link="rear_right_wheel"/>
    <origin rpy="1.5707963267948966 0 0" xyz="0 -0.25 0"/>
    <axis xyz="0 0 1"/>
  </joint>
  <link name="rear_right_wheel">
    <visual>
      <geometry>
        <cylinder length="0.04" radius="0.05"/>
      </geometry>
      <material name="black"/>
    </visual>
    <collision>
      <geometry>
        <cylinder length="0.04" radius="0.05"/>
      </geometry>
    </collision>
    <inertial>
      <origin rpy="0 0 0" xyz="0 0 0"/>
      <mass value="0.1"/>
      <inertia ixx="7.583333333333335e-05" ixy="0.0" ixz="0.0" iyy="7.583333333333335e-05" iyz="0.0" izz="0.00012500000000000003"/>
    </inertial>
  </link>
  <gazebo reference="rear_right_wheel">
    <material>Gazebo/Black</material>
  </gazebo>
  <!-- Joint for Sliding in X-Direction -->
  <joint name="top_hemisphere_joint" type="prismatic">
    <parent link="base_link"/>
    <child link="top_hemisphere"/>
    <origin xyz="0.15 0 0.3"/>
    <axis xyz="1 0 0"/>
    <!-- Allows sliding in the X-axis direction -->
    <limit effort="1.0" lower="-0.1" upper="0.1" velocity="0.1"/>
  </joint>
  <!-- Semi-Hemisphere on Top with Sliding X-Direction Capability -->
  <link name="top_hemisphere">
    <visual>
      <origin xyz="0 0 0"/>
      <geometry>
        <sphere radius="0.15"/>
      </geometry>
      <material name="red"/>
    </visual>
    <collision>
      <origin xyz="0 0 0"/>
      <geometry>
        <sphere radius="0.15"/>
      </geometry>
    </collision>
    <inertial>
      <origin rpy="0 0 0" xyz="0 0 0"/>
      <mass value="0.2"/>
      <inertia ixx="0.0018000000000000004" ixy="0.0" ixz="0.0" iyy="0.0018000000000000004" iyz="0.0" izz="0.0018000000000000004"/>
    </inertial>
  </link>
  <gazebo reference="top_hemisphere">
    <material>Gazebo/Red</material>
  </gazebo>
</robot>
